Sun Jan 10 14:01:07 EET 2021 : Apache Derby Network Server - 10.10.2.0 - (1582446) started and ready to accept connections on port 1527
----------------------------------------------------------------
Sun Jan 10 14:01:08 EET 2021:
Booting Derby version The Apache Software Foundation - Apache Derby - 10.10.2.0 - (1582446): instance a816c00e-0176-ebf4-f4b3-000017f60280 
on database directory C:\Users\moayy\Desktop\JAVA BUFFERED\1306180132_vizeProject\nyp_proje with class loader sun.misc.Launcher$AppClassLoader@1d44bcfa 
Loaded from file:/C:/Users/moayy/Downloads/db-derby-10.10.2.0-bin/db-derby-10.10.2.0-bin/lib/derby.jar
java.vendor=Oracle Corporation
java.runtime.version=1.8.0_271-b09
user.dir=C:\Users\moayy\Downloads\db-derby-10.10.2.0-bin\db-derby-10.10.2.0-bin
os.name=Windows 10
os.arch=amd64
os.version=10.0
derby.system.home=C:\Users\moayy\Desktop\JAVA BUFFERED\1306180132_vizeProject
Database Class Loader started - derby.database.classpath=''
Sun Jan 10 14:01:26 EET 2021 Thread[DRDAConnThread_3,5,main] (XID = 389), (SESSIONID = 2), (DATABASE = nyp_proje), (DRDAID = {2}), Cleanup action starting
java.sql.SQLNonTransientConnectionException: Connection authentication failure occurred.  Reason: Invalid authentication..
	at org.apache.derby.impl.jdbc.SQLExceptionFactory40.getSQLException(Unknown Source)
	at org.apache.derby.impl.jdbc.Util.newEmbedSQLException(Unknown Source)
	at org.apache.derby.impl.jdbc.Util.newEmbedSQLException(Unknown Source)
	at org.apache.derby.impl.jdbc.Util.generateCsSQLException(Unknown Source)
	at org.apache.derby.impl.jdbc.EmbedConnection.newSQLException(Unknown Source)
	at org.apache.derby.impl.jdbc.EmbedConnection.checkUserCredentials(Unknown Source)
	at org.apache.derby.impl.jdbc.EmbedConnection.<init>(Unknown Source)
	at org.apache.derby.impl.jdbc.EmbedConnection40.<init>(Unknown Source)
	at org.apache.derby.jdbc.Driver40.getNewEmbedConnection(Unknown Source)
	at org.apache.derby.jdbc.InternalDriver.connect(Unknown Source)
	at org.apache.derby.jdbc.Driver20.connect(Unknown Source)
	at org.apache.derby.jdbc.EmbeddedDriver.connect(Unknown Source)
	at org.apache.derby.impl.drda.Database.makeConnection(Unknown Source)
	at org.apache.derby.impl.drda.DRDAConnThread.getConnFromDatabaseName(Unknown Source)
	at org.apache.derby.impl.drda.DRDAConnThread.verifyUserIdPassword(Unknown Source)
	at org.apache.derby.impl.drda.DRDAConnThread.parseSECCHK(Unknown Source)
	at org.apache.derby.impl.drda.DRDAConnThread.parseDRDAConnection(Unknown Source)
	at org.apache.derby.impl.drda.DRDAConnThread.processCommands(Unknown Source)
	at org.apache.derby.impl.drda.DRDAConnThread.run(Unknown Source)
Caused by: java.sql.SQLException: Connection authentication failure occurred.  Reason: Invalid authentication..
	at org.apache.derby.impl.jdbc.SQLExceptionFactory.getSQLException(Unknown Source)
	at org.apache.derby.impl.jdbc.SQLExceptionFactory40.wrapArgsForTransportAcrossDRDA(Unknown Source)
	... 19 more
============= begin nested exception, level (1) ===========
java.sql.SQLException: Connection authentication failure occurred.  Reason: Invalid authentication..
	at org.apache.derby.impl.jdbc.SQLExceptionFactory.getSQLException(Unknown Source)
	at org.apache.derby.impl.jdbc.SQLExceptionFactory40.wrapArgsForTransportAcrossDRDA(Unknown Source)
	at org.apache.derby.impl.jdbc.SQLExceptionFactory40.getSQLException(Unknown Source)
	at org.apache.derby.impl.jdbc.Util.newEmbedSQLException(Unknown Source)
	at org.apache.derby.impl.jdbc.Util.newEmbedSQLException(Unknown Source)
	at org.apache.derby.impl.jdbc.Util.generateCsSQLException(Unknown Source)
	at org.apache.derby.impl.jdbc.EmbedConnection.newSQLException(Unknown Source)
	at org.apache.derby.impl.jdbc.EmbedConnection.checkUserCredentials(Unknown Source)
	at org.apache.derby.impl.jdbc.EmbedConnection.<init>(Unknown Source)
	at org.apache.derby.impl.jdbc.EmbedConnection40.<init>(Unknown Source)
	at org.apache.derby.jdbc.Driver40.getNewEmbedConnection(Unknown Source)
	at org.apache.derby.jdbc.InternalDriver.connect(Unknown Source)
	at org.apache.derby.jdbc.Driver20.connect(Unknown Source)
	at org.apache.derby.jdbc.EmbeddedDriver.connect(Unknown Source)
	at org.apache.derby.impl.drda.Database.makeConnection(Unknown Source)
	at org.apache.derby.impl.drda.DRDAConnThread.getConnFromDatabaseName(Unknown Source)
	at org.apache.derby.impl.drda.DRDAConnThread.verifyUserIdPassword(Unknown Source)
	at org.apache.derby.impl.drda.DRDAConnThread.parseSECCHK(Unknown Source)
	at org.apache.derby.impl.drda.DRDAConnThread.parseDRDAConnection(Unknown Source)
	at org.apache.derby.impl.drda.DRDAConnThread.processCommands(Unknown Source)
	at org.apache.derby.impl.drda.DRDAConnThread.run(Unknown Source)
============= end nested exception, level (1) ===========
Cleanup action completed
Sun Jan 10 14:01:26 EET 2021 Thread[DRDAConnThread_3,5,main] (DATABASE = nyp_proje), (DRDAID = {2}), Connection authentication failure occurred.  Reason: Invalid authentication..
Sun Jan 10 14:01:56 EET 2021 Thread[DRDAConnThread_3,5,main] (XID = 390), (SESSIONID = 3), (DATABASE = nyp_proje), (DRDAID = {3}), Cleanup action starting
java.sql.SQLNonTransientConnectionException: Connection authentication failure occurred.  Reason: Invalid authentication..
	at org.apache.derby.impl.jdbc.SQLExceptionFactory40.getSQLException(Unknown Source)
	at org.apache.derby.impl.jdbc.Util.newEmbedSQLException(Unknown Source)
	at org.apache.derby.impl.jdbc.Util.newEmbedSQLException(Unknown Source)
	at org.apache.derby.impl.jdbc.Util.generateCsSQLException(Unknown Source)
	at org.apache.derby.impl.jdbc.EmbedConnection.newSQLException(Unknown Source)
	at org.apache.derby.impl.jdbc.EmbedConnection.checkUserCredentials(Unknown Source)
	at org.apache.derby.impl.jdbc.EmbedConnection.<init>(Unknown Source)
	at org.apache.derby.impl.jdbc.EmbedConnection40.<init>(Unknown Source)
	at org.apache.derby.jdbc.Driver40.getNewEmbedConnection(Unknown Source)
	at org.apache.derby.jdbc.InternalDriver.connect(Unknown Source)
	at org.apache.derby.jdbc.Driver20.connect(Unknown Source)
	at org.apache.derby.jdbc.EmbeddedDriver.connect(Unknown Source)
	at org.apache.derby.impl.drda.Database.makeConnection(Unknown Source)
	at org.apache.derby.impl.drda.DRDAConnThread.getConnFromDatabaseName(Unknown Source)
	at org.apache.derby.impl.drda.DRDAConnThread.verifyUserIdPassword(Unknown Source)
	at org.apache.derby.impl.drda.DRDAConnThread.parseSECCHK(Unknown Source)
	at org.apache.derby.impl.drda.DRDAConnThread.parseDRDAConnection(Unknown Source)
	at org.apache.derby.impl.drda.DRDAConnThread.processCommands(Unknown Source)
	at org.apache.derby.impl.drda.DRDAConnThread.run(Unknown Source)
Caused by: java.sql.SQLException: Connection authentication failure occurred.  Reason: Invalid authentication..
	at org.apache.derby.impl.jdbc.SQLExceptionFactory.getSQLException(Unknown Source)
	at org.apache.derby.impl.jdbc.SQLExceptionFactory40.wrapArgsForTransportAcrossDRDA(Unknown Source)
	... 19 more
============= begin nested exception, level (1) ===========
java.sql.SQLException: Connection authentication failure occurred.  Reason: Invalid authentication..
	at org.apache.derby.impl.jdbc.SQLExceptionFactory.getSQLException(Unknown Source)
	at org.apache.derby.impl.jdbc.SQLExceptionFactory40.wrapArgsForTransportAcrossDRDA(Unknown Source)
	at org.apache.derby.impl.jdbc.SQLExceptionFactory40.getSQLException(Unknown Source)
	at org.apache.derby.impl.jdbc.Util.newEmbedSQLException(Unknown Source)
	at org.apache.derby.impl.jdbc.Util.newEmbedSQLException(Unknown Source)
	at org.apache.derby.impl.jdbc.Util.generateCsSQLException(Unknown Source)
	at org.apache.derby.impl.jdbc.EmbedConnection.newSQLException(Unknown Source)
	at org.apache.derby.impl.jdbc.EmbedConnection.checkUserCredentials(Unknown Source)
	at org.apache.derby.impl.jdbc.EmbedConnection.<init>(Unknown Source)
	at org.apache.derby.impl.jdbc.EmbedConnection40.<init>(Unknown Source)
	at org.apache.derby.jdbc.Driver40.getNewEmbedConnection(Unknown Source)
	at org.apache.derby.jdbc.InternalDriver.connect(Unknown Source)
	at org.apache.derby.jdbc.Driver20.connect(Unknown Source)
	at org.apache.derby.jdbc.EmbeddedDriver.connect(Unknown Source)
	at org.apache.derby.impl.drda.Database.makeConnection(Unknown Source)
	at org.apache.derby.impl.drda.DRDAConnThread.getConnFromDatabaseName(Unknown Source)
	at org.apache.derby.impl.drda.DRDAConnThread.verifyUserIdPassword(Unknown Source)
	at org.apache.derby.impl.drda.DRDAConnThread.parseSECCHK(Unknown Source)
	at org.apache.derby.impl.drda.DRDAConnThread.parseDRDAConnection(Unknown Source)
	at org.apache.derby.impl.drda.DRDAConnThread.processCommands(Unknown Source)
	at org.apache.derby.impl.drda.DRDAConnThread.run(Unknown Source)
============= end nested exception, level (1) ===========
Cleanup action completed
Sun Jan 10 14:01:56 EET 2021 Thread[DRDAConnThread_3,5,main] (DATABASE = nyp_proje), (DRDAID = {3}), Connection authentication failure occurred.  Reason: Invalid authentication..
----------------------------------------------------------------
Sun Jan 10 14:03:31 EET 2021: Shutting down Derby engine
----------------------------------------------------------------
Sun Jan 10 14:03:31 EET 2021:
Shutting down instance a816c00e-0176-ebf4-f4b3-000017f60280 on database directory C:\Users\moayy\Desktop\JAVA BUFFERED\1306180132_vizeProject\nyp_proje with class loader sun.misc.Launcher$AppClassLoader@1d44bcfa 
----------------------------------------------------------------
